{
    "error": "Error executing biom command: Traceback (most recent call last):\n  File \"\/usr\/local
\/lib\/python3.5\/site-packages\/biom_format-2.1.5-py3.5-linux-x86_64.egg\/biom\/parse.py\", line 654
, in load_table\n    table = parse_biom_table(fp)\n  File \"\/usr\/local\/lib\/python3.5\/site-packages
\/biom_format-2.1.5-py3.5-linux-x86_64.egg\/biom\/parse.py\", line 408, in parse_biom_table\n    t =
 Table.from_tsv(fp, None, None, lambda x: x)\n  File \"\/usr\/local\/lib\/python3.5\/site-packages\/biom_format-2
.1.5-py3.5-linux-x86_64.egg\/biom\/table.py\", line 3893, in from_tsv\n    t_md_name) = Table._extract_data_from_tsv
(lines, **kwargs)\n  File \"\/usr\/local\/lib\/python3.5\/site-packages\/biom_format-2.1.5-py3.5-linux-x86_64
.egg\/biom\/table.py\", line 4009, in _extract_data_from_tsv\n    md_name = header[-1]\nIndexError: list
 index out of range\n\nDuring handling of the above exception, another exception occurred:\n\nTraceback
 (most recent call last):\n  File \"\/usr\/local\/bin\/biom\", line 6, in <module>\n    sys.exit(biom
.cli.cli())\n  File \"\/usr\/local\/lib\/python3.5\/site-packages\/click\/core.py\", line 716, in __call__
\n    return self.main(*args, **kwargs)\n  File \"\/usr\/local\/lib\/python3.5\/site-packages\/click
\/core.py\", line 696, in main\n    rv = self.invoke(ctx)\n  File \"\/usr\/local\/lib\/python3.5\/site-packages
\/click\/core.py\", line 1060, in invoke\n    return _process_result(sub_ctx.command.invoke(sub_ctx)
)\n  File \"\/usr\/local\/lib\/python3.5\/site-packages\/click\/core.py\", line 889, in invoke\n    return
 ctx.invoke(self.callback, **ctx.params)\n  File \"\/usr\/local\/lib\/python3.5\/site-packages\/click
\/core.py\", line 534, in invoke\n    return callback(*args, **kwargs)\n  File \"\/usr\/local\/lib\/python3
.5\/site-packages\/biom_format-2.1.5-py3.5-linux-x86_64.egg\/biom\/cli\/table_converter.py\", line 114
, in convert\n    table = load_table(input_fp)\n  File \"\/usr\/local\/lib\/python3.5\/site-packages
\/biom_format-2.1.5-py3.5-linux-x86_64.egg\/biom\/parse.py\", line 656, in load_table\n    raise TypeError
(\"%s does not appear to be a BIOM file!\" % f)\nTypeError: \/tmp\/biomcsR4WGaF does not appear to be
 a BIOM file! 1"
}
